Workbook

Sheet 요약
A1: 테스트 로그 | B1: 설명 | D1: 테스트 결과 종류 | E1: 설명
B2: 시간단위 정상 동작 로그 | D2: Pass | E2: 테스트 성공
B3: 분단위 정상 동작 로그 | D3: Fail | E3: 테스트 실패
B4: 초기 Slave 통신이 동작 도중 복구되는 경우의 로그 (3분단위 통신 동작, 20분) | D4: None | E4: 의미없는 테스트로 생략된 경우 (참고사항 확인)
B5: Slave 및 무선통신 실패 로그 (3분단위 통신 동작, 1시간) | D5: Skip | E5: 특정 이유로 테스트를 생략한 경우 (참고사항 확인)
A6: 장비 확인 및 소모전류테스트 로그 참조. | B6: Sleep 소모전류
A7: 장비 확인 및 소모전류테스트 로그 참조. | B7: IDLE 소모전류 | D7: 대분류 | E7: 총 개수 | F7: 총합 | G7: 결과
B8: Active 소모전류 계산 | G8: Pass | H8: Fail | I8: Skip | J8: None
D9: ='테스트 결과'!A2 -> 주기동작 (A) | E9: =COUNTIF('테스트 결과'!C:C,"A-*") -> 6 | F9: =G9+H9+I9+J9 -> 6 | G9: =COUNTIFS('테스트 결과'!C:C, "A-*", '테스트 결과'!D:D, G8) -> 6 | H9: =COUNTIFS('테스트 결과'!C:C, "A-*", '테스트 결과'!D:D, H8) -> 0 | I9: =COUNTIFS('테스트 결과'!C:C, "A-*", '테스트 결과'!D:D, I8) -> 0 | J9: =COUNTIFS('테스트 결과'!C:C, "A-*", '테스트 결과'!D:D, J8) -> 0
D10: ='테스트 결과'!A8 -> 무선통신 (B) | E10: =COUNTIF('테스트 결과'!C:C,"B-*") -> 11 | F10: =G10+H10+I10+J10 -> 11 | G10: =COUNTIFS('테스트 결과'!C:C, "B-*", '테스트 결과'!D:D, G8) -> 11 | H10: =COUNTIFS('테스트 결과'!C:C, "B-*", '테스트 결과'!D:D, H8) -> 0 | I10: =COUNTIFS('테스트 결과'!C:C, "B-*", '테스트 결과'!D:D, I8) -> 0 | J10: =COUNTIFS('테스트 결과'!C:C, "B-*", '테스트 결과'!D:D, J8) -> 0
D11: ='테스트 결과'!A19 -> NFC 동작 (C) | E11: =COUNTIF('테스트 결과'!C:C,"C-*") -> 10 | F11: =G11+H11+I11+J11 -> 10 | G11: =COUNTIFS('테스트 결과'!C:C, "C-*", '테스트 결과'!D:D, G8) -> 10 | H11: =COUNTIFS('테스트 결과'!C:C, "C-*", '테스트 결과'!D:D, H8) -> 0 | I11: =COUNTIFS('테스트 결과'!C:C, "C-*", '테스트 결과'!D:D, I8) -> 0 | J11: =COUNTIFS('테스트 결과'!C:C, "C-*", '테스트 결과'!D:D, J8) -> 0
D12: ='테스트 결과'!A29 -> RF424/433 (D) | E12: =COUNTIF('테스트 결과'!C:C,"D-*") -> 12 | F12: =G12+H12+I12+J12 -> 12 | G12: =COUNTIFS('테스트 결과'!C:C, "D-*", '테스트 결과'!D:D, G8) -> 12 | H12: =COUNTIFS('테스트 결과'!C:C, "D-*", '테스트 결과'!D:D, H8) -> 0 | I12: =COUNTIFS('테스트 결과'!C:C, "D-*", '테스트 결과'!D:D, I8) -> 0 | J12: =COUNTIFS('테스트 결과'!C:C, "D-*", '테스트 결과'!D:D, J8) -> 0
D13: ='테스트 결과'!A41 -> 계량기 통신 (E) | E13: =COUNTIF('테스트 결과'!C:C,"E-*") -> 5 | F13: =G13+H13+I13+J13 -> 5 | G13: =COUNTIFS('테스트 결과'!C:C, "E-*", '테스트 결과'!D:D, G8) -> 5 | H13: =COUNTIFS('테스트 결과'!C:C, "E-*", '테스트 결과'!D:D, H8) -> 0 | I13: =COUNTIFS('테스트 결과'!C:C, "E-*", '테스트 결과'!D:D, I8) -> 0 | J13: =COUNTIFS('테스트 결과'!C:C, "E-*", '테스트 결과'!D:D, J8) -> 0
D14: ='테스트 결과'!A46 -> 소모전류 (G) | E14: =COUNTIF('테스트 결과'!C:C,"G-*") -> 5 | F14: =G14+H14+I14+J14 -> 0 | G14: =COUNTIFS('테스트 결과'!C:C, "G-*", '테스트 결과'!D:D, G8) -> 0 | H14: =COUNTIFS('테스트 결과'!C:C, "G-*", '테스트 결과'!D:D, H8) -> 0 | I14: =COUNTIFS('테스트 결과'!C:C, "G-*", '테스트 결과'!D:D, I8) -> 0 | J14: =COUNTIFS('테스트 결과'!C:C, "G-*", '테스트 결과'!D:D, J8) -> 0
D15: 총 합 | E15: =E9+E10+E11+E12+E13+E14 -> 49 | F15: =F9+F10+F11+F12+F13+F14 -> 44 | G15: =G9+G10+G11+G12+G13+G14 -> 44 | H15: =H9+H10+H11+H12+H13+H14 -> 0 | I15: =I9+I10+I11+I12+I13+I14 -> 0 | J15: =J9+J10+J11+J12+J13+J14 -> 0

Sheet 테스트 결과
A1: 대분류 | B1: 소분류 | C1: Test No | D1: 결과 | E1: Test Case
A2: 주기동작 (A) | B2: 시간단위 (A) | C2: A-A-1 | D2: Pass | E2: 시간단위 주기 검침 알람이 정상적으로 동작하는지?
C3: A-A-2 | D3: Pass | E3: 시간단위 주기 보고 알람이 정상적으로 동작하는지?
C4: A-A-3 | D4: Pass | E4: 시간단위 주기 검침/보고 완료 후 Sleep mode로 진입하는지?
B5: 분단위 (B) | C5: A-B-1 | D5: Pass | E5: 분단위 주기 검침 알람이 정상적으로 동작하는지?
C6: A-B-2 | D6: Pass | E6: 분단위 주기 보고 알람이 정상적으로 동작하는지?
C7: A-B-3 | D7: Pass | E7: 분단위 주기 검침/보고 완료 후 Sleep mode로 진입하는지?
A8: 무선통신 (B) | B8: 검침 데이터 (A) | C8: B-A-1 | D8: Pass | E8: 즉시검침 데이터 전송이 정상적으로 동작하는지?
C9: B-A-2 | D9: Pass | E9: 주기검침 데이터 전송이 정상적으로 동작하는지?
C10: B-A-3 | D10: Pass | E10: 검침 데이터 전송 재시도가 정상적으로 동작하는지?
C11: B-A-4 | D11: Pass | E11: 검침 데이터 전송 성공 후 저장된 모든 검침 데이터를 삭제하는지? (주기보고)
C12: B-A-5 | D12: Pass | E12: 검침 데이터 전송 실패 시 다음 주기 전송을 위해 데이터를 보존하는지? (주기보고)
C13: B-A-6 | D13: Pass | E13: 검침 데이터 전송 시 전송 실패로 누적된 데이터도 함께 전송하는지? (주기보고)
B14: 망접속 (B) | C14: B-B-1 | D14: Pass | E14: 망 접속 재시도가 정상적으로 동작하는지? (LoRa의 경우 Join 재시도 동작)
B15: 인증 (C) | C15: B-C-1 | D15: Pass | E15: 타사/통신사 플랫폼 인증 동작이 일정 주기로 다시 동작하는지?
B16: 시간동기화 (D) | C16: B-D-1 | D16: Pass | E16: 시간동기화 동작이 단말기 최초 부팅할 때 부터 동작하는지?
C17: B-D-2 | D17: Pass | E17: 시간동기화 동작 실패 시 주기적으로 재시도를 하는지?
C18: B-D-3 | D18: Pass | E18: 시간동기화 동작가 일정 주기로 다시 동작하는지? (최소 24시간내 1번)
A19: NFC 동작 (C) | B19: 서버 접속 (A) | C19: C-A-1 | D19: Pass | E19: 서버 접속 요청이 정상적으로 동작하는지?
C20: C-A-2 | D20: Pass | E20: 서버 접속 요청 시도 시 진행 및 완료 여부를 확인할 수 있는지?
C21: C-A-3 | D21: Pass | E21: 서버 접속 상태정보 요청이 정상적으로 동작하는지?
B22: 장치 리셋 (B) | C22: C-B-1 | D22: Pass | E22: 장치 리셋 요청이 정상적으로 동작하는지?
B23: 설정 (C) | C23: C-C-1 | D23: Pass | E23: 서버 접속 설정 업데이트 요청이 정상적으로 동작하는지?
C24: C-C-2 | D24: Pass | E24: 검침/보고 주기 업데이트 요청이 정상적으로 동작하는지?
C25: C-C-3 | D25: Pass | E25: 설정 정보 읽기/저장 요청이 정상적으로 동작하는지?
B26: 검침 (D) | C26: C-D-1 | D26: Pass | E26: 즉시 검침 요청이 정상적으로 동작하는지?
C27: C-D-2 | D27: Pass | E27: 즉시 검침 동작 시도 시 진행 및 완료 여부를 확인할 수 있는지? (다른 방식의 요청에 의한 즉시 검침을 수행하더라도 확인가능 해야 함.)
C28: C-D-3 | D28: Pass | E28: 즉시 검침 동작 시도 시 무선통신 동작을 인지하고 Busy를 보고하는지?
A29: RF424/433 (D) | B29: 검침 (A) | C29: D-A-1 | D29: Pass | E29: 주기 검침 데이터 요청이 정상적으로 동작하는지?
C30: D-A-2 | D30: Pass | E30: 주기 검침 데이터 요청 재시도가 정상적으로 동작하는지?
C31: D-A-3 | D31: Pass | E31: 즉각 검침 데이터 요청이 정상적으로 동작하는지?
C32: D-A-4 | D32: Pass | E32: 즉각 검침 데이터 요청 재시도가 정상적으로 동작하는지?
C33: D-A-5 | D33: Pass | E33: 검침 데이터를 못읽어 올 경우 MT_DOWN으로 저장하는지?
C34: D-A-6 | D34: Pass | E34: 검침 데이터를 0개 읽어 올 경우 0개로 처리하는지? (저장안하고 그대로 처리.)
C35: D-A-7 | D35: Pass | E35: 주기검침 데이터 누적 제한 초과 시 알고리즘에 맞게 데이터를 정리하는지? (ex : 1시간 단위를 2시간 단위 데이터로 변경.)
B36: 시간동기화 (C) | C36: D-C-1 | D36: Pass | E36: 시간동기화 동작이 단말 부팅할 때 부터 동작하는지?
C37: D-C-2 | D37: Pass | E37: 시간동기화 동작 실패 시 주기적으로 재시도를 하는지?
B38: 검침기 정보 (D) | C38: D-D-1 | D38: Pass | E38: 검침기 정보 업데이트가 단말 부팅할 때 부터 동작하는지?
C39: D-D-2 | D39: Pass | E39: 검침기 정보 업데이트 실패 시 주기적으로 재시도를 하는지?
C40: D-D-3 | D40: Pass | E40: 검침기 정보 업데이트가 주기적으로 동작하는지?
...

Sheet 참고사항
A1: Test No | B1: 결과 | C1: 참고사항
